<?xml version="1.0" encoding="UTF-8"?>
<testng-results ignored="0" total="5" passed="3" failed="1" skipped="1">
  <reporter-output>
  </reporter-output>
  <suite started-at="2023-09-23T07:30:51Z" name="Suite" finished-at="2023-09-23T07:31:29Z" duration-ms="38040">
    <groups>
      <group name="ErrorHandling">
        <method signature="ErrorValidationsTest.loginErrorValidation()[pri:0, instance:practise.tests.ErrorValidationsTest@4426bff1]" name="loginErrorValidation" class="practise.tests.ErrorValidationsTest"/>
      </group> <!-- ErrorHandling -->
    </groups>
    <test started-at="2023-09-23T07:30:51Z" name="Submit Order Test" finished-at="2023-09-23T07:31:12Z" duration-ms="20987">
      <class name="practise.tests.SubmitOrderTest">
        <test-method is-config="true" signature="launchApplication()[pri:0, instance:practise.tests.SubmitOrderTest@22f31dec]" started-at="2023-09-23T07:30:51Z" name="launchApplication" finished-at="2023-09-23T07:31:00Z" duration-ms="8591" status="PASS">
          <reporter-output>
          </reporter-output>
        </test-method> <!-- launchApplication -->
        <test-method signature="submitOrder()[pri:0, instance:practise.tests.SubmitOrderTest@22f31dec]" started-at="2023-09-23T07:31:00Z" name="submitOrder" finished-at="2023-09-23T07:31:04Z" duration-ms="3883" status="PASS">
          <reporter-output>
          </reporter-output>
        </test-method> <!-- submitOrder -->
        <test-method is-config="true" signature="launchApplication()[pri:0, instance:practise.tests.SubmitOrderTest@22f31dec]" started-at="2023-09-23T07:31:04Z" name="launchApplication" finished-at="2023-09-23T07:31:10Z" duration-ms="6617" status="PASS">
          <reporter-output>
          </reporter-output>
        </test-method> <!-- launchApplication -->
        <test-method signature="OrderHistoryTest()[pri:0, instance:practise.tests.SubmitOrderTest@22f31dec]" started-at="2023-09-23T07:31:10Z" name="OrderHistoryTest" finished-at="2023-09-23T07:31:12Z" depends-on-methods="practise.tests.SubmitOrderTest.submitOrder" duration-ms="1869" status="PASS">
          <reporter-output>
          </reporter-output>
        </test-method> <!-- OrderHistoryTest -->
      </class> <!-- practise.tests.SubmitOrderTest -->
    </test> <!-- Submit Order Test -->
    <test started-at="2023-09-23T07:30:51Z" name="Error Validations Test" finished-at="2023-09-23T07:31:29Z" duration-ms="38040">
      <class name="practise.tests.ErrorValidationsTest">
        <test-method is-config="true" signature="launchApplication()[pri:0, instance:practise.tests.ErrorValidationsTest@4426bff1]" started-at="2023-09-23T07:30:51Z" name="launchApplication" finished-at="2023-09-23T07:31:01Z" duration-ms="9480" status="PASS">
          <reporter-output>
          </reporter-output>
        </test-method> <!-- launchApplication -->
        <test-method signature="loginErrorValidation()[pri:0, instance:practise.tests.ErrorValidationsTest@4426bff1]" started-at="2023-09-23T07:31:01Z" name="loginErrorValidation" finished-at="2023-09-23T07:31:02Z" duration-ms="956" status="SKIP">
          <exception class="java.lang.AssertionError">
            <message>
              <![CDATA[expected [Incorrect email or password.] but found [Incorrect email password.]]]>
            </message>
            <full-stacktrace>
              <![CDATA[java.lang.AssertionError: expected [Incorrect email or password.] but found [Incorrect email password.]
at org.testng.Assert.fail(Assert.java:96)
at org.testng.Assert.failNotEquals(Assert.java:776)
at org.testng.Assert.assertEqualsImpl(Assert.java:137)
at org.testng.Assert.assertEquals(Assert.java:118)
at org.testng.Assert.assertEquals(Assert.java:453)
at org.testng.Assert.assertEquals(Assert.java:463)
at practise.tests.ErrorValidationsTest.loginErrorValidation(ErrorValidationsTest.java:22)
at java.base/jdk.internal.reflect.NativeMethodAccessorImpl.invoke0(Native Method)
at java.base/jdk.internal.reflect.NativeMethodAccessorImpl.invoke(NativeMethodAccessorImpl.java:77)
at java.base/jdk.internal.reflect.DelegatingMethodAccessorImpl.invoke(DelegatingMethodAccessorImpl.java:43)
at java.base/java.lang.reflect.Method.invoke(Method.java:568)
at org.testng.internal.MethodInvocationHelper.invokeMethod(MethodInvocationHelper.java:124)
at org.testng.internal.Invoker.invokeMethod(Invoker.java:583)
at org.testng.internal.Invoker.invokeTestMethod(Invoker.java:719)
at org.testng.internal.Invoker.invokeTestMethods(Invoker.java:989)
at org.testng.internal.TestMethodWorker.invokeTestMethods(TestMethodWorker.java:125)
at org.testng.internal.TestMethodWorker.run(TestMethodWorker.java:109)
at org.testng.TestRunner.privateRun(TestRunner.java:648)
at org.testng.TestRunner.run(TestRunner.java:505)
at org.testng.SuiteRunner.runTest(SuiteRunner.java:455)
at org.testng.SuiteRunner.access$000(SuiteRunner.java:40)
at org.testng.SuiteRunner$SuiteWorker.run(SuiteRunner.java:489)
at org.testng.internal.thread.ThreadUtil$1.call(ThreadUtil.java:52)
at java.base/java.util.concurrent.FutureTask.run(FutureTask.java:264)
at java.base/java.util.concurrent.ThreadPoolExecutor.runWorker(ThreadPoolExecutor.java:1136)
at java.base/java.util.concurrent.ThreadPoolExecutor$Worker.run(ThreadPoolExecutor.java:635)
at java.base/java.lang.Thread.run(Thread.java:833)
]]>
            </full-stacktrace>
          </exception> <!-- java.lang.AssertionError -->
          <reporter-output>
          </reporter-output>
        </test-method> <!-- loginErrorValidation -->
        <test-method is-config="true" signature="launchApplication()[pri:0, instance:practise.tests.ErrorValidationsTest@4426bff1]" started-at="2023-09-23T07:31:02Z" name="launchApplication" finished-at="2023-09-23T07:31:08Z" duration-ms="6089" status="PASS">
          <reporter-output>
          </reporter-output>
        </test-method> <!-- launchApplication -->
        <test-method signature="loginErrorValidation()[pri:0, instance:practise.tests.ErrorValidationsTest@4426bff1]" started-at="2023-09-23T07:31:08Z" name="loginErrorValidation" finished-at="2023-09-23T07:31:09Z" duration-ms="813" status="FAIL">
          <exception class="java.lang.AssertionError">
            <message>
              <![CDATA[expected [Incorrect email or password.] but found [Incorrect email password.]]]>
            </message>
            <full-stacktrace>
              <![CDATA[java.lang.AssertionError: expected [Incorrect email or password.] but found [Incorrect email password.]
at org.testng.Assert.fail(Assert.java:96)
at org.testng.Assert.failNotEquals(Assert.java:776)
at org.testng.Assert.assertEqualsImpl(Assert.java:137)
at org.testng.Assert.assertEquals(Assert.java:118)
at org.testng.Assert.assertEquals(Assert.java:453)
at org.testng.Assert.assertEquals(Assert.java:463)
at practise.tests.ErrorValidationsTest.loginErrorValidation(ErrorValidationsTest.java:22)
at java.base/jdk.internal.reflect.NativeMethodAccessorImpl.invoke0(Native Method)
at java.base/jdk.internal.reflect.NativeMethodAccessorImpl.invoke(NativeMethodAccessorImpl.java:77)
at java.base/jdk.internal.reflect.DelegatingMethodAccessorImpl.invoke(DelegatingMethodAccessorImpl.java:43)
at java.base/java.lang.reflect.Method.invoke(Method.java:568)
at org.testng.internal.MethodInvocationHelper.invokeMethod(MethodInvocationHelper.java:124)
at org.testng.internal.Invoker.invokeMethod(Invoker.java:583)
at org.testng.internal.Invoker.retryFailed(Invoker.java:839)
at org.testng.internal.Invoker.invokeTestMethods(Invoker.java:1010)
at org.testng.internal.TestMethodWorker.invokeTestMethods(TestMethodWorker.java:125)
at org.testng.internal.TestMethodWorker.run(TestMethodWorker.java:109)
at org.testng.TestRunner.privateRun(TestRunner.java:648)
at org.testng.TestRunner.run(TestRunner.java:505)
at org.testng.SuiteRunner.runTest(SuiteRunner.java:455)
at org.testng.SuiteRunner.access$000(SuiteRunner.java:40)
at org.testng.SuiteRunner$SuiteWorker.run(SuiteRunner.java:489)
at org.testng.internal.thread.ThreadUtil$1.call(ThreadUtil.java:52)
at java.base/java.util.concurrent.FutureTask.run(FutureTask.java:264)
at java.base/java.util.concurrent.ThreadPoolExecutor.runWorker(ThreadPoolExecutor.java:1136)
at java.base/java.util.concurrent.ThreadPoolExecutor$Worker.run(ThreadPoolExecutor.java:635)
at java.base/java.lang.Thread.run(Thread.java:833)
]]>
            </full-stacktrace>
          </exception> <!-- java.lang.AssertionError -->
          <reporter-output>
          </reporter-output>
        </test-method> <!-- loginErrorValidation -->
        <test-method is-config="true" signature="launchApplication()[pri:0, instance:practise.tests.ErrorValidationsTest@4426bff1]" started-at="2023-09-23T07:31:09Z" name="launchApplication" finished-at="2023-09-23T07:31:18Z" duration-ms="9595" status="PASS">
          <reporter-output>
          </reporter-output>
        </test-method> <!-- launchApplication -->
        <test-method signature="productErrorValidation()[pri:0, instance:practise.tests.ErrorValidationsTest@4426bff1]" started-at="2023-09-23T07:31:18Z" name="productErrorValidation" finished-at="2023-09-23T07:31:29Z" duration-ms="11081" status="PASS">
          <reporter-output>
          </reporter-output>
        </test-method> <!-- productErrorValidation -->
      </class> <!-- practise.tests.ErrorValidationsTest -->
    </test> <!-- Error Validations Test -->
  </suite> <!-- Suite -->
</testng-results>
